<!-- UR5e Body Structure -->
<mujoco>
  <worldbody>
    <!-- UR5e Base -->
    <body name="ur5e_base" pos="0 0 0.8" quat="0 0 0 -1">
      <inertial mass="4.0" pos="0 0 0" diaginertia="0.00443333156 0.00443333156 0.0072"/>
      <geom mesh="base_0" material="black" type="mesh" contype="0" conaffinity="0" group="2"/>
      <geom mesh="base_1" material="jointgray" type="mesh" contype="0" conaffinity="0" group="2"/>
      
      <!-- Robot base coordinate frame -->
      <site name="robot_frame" pos="0 0 0" size="0.05" type="sphere" rgba="1 1 0 0.5"/>
      <geom name="robot_x_axis" type="cylinder" pos="0.03 0 0" size="0.003 0.06" rgba="1 0 0 1" quat="0.707 0 0.707 0"/>
      <geom name="robot_y_axis" type="cylinder" pos="0 0.03 0" size="0.003 0.06" rgba="0 1 0 1" quat="0.707 0.707 0 0"/>
      <geom name="robot_z_axis" type="cylinder" pos="0 0 0.03" size="0.003 0.06" rgba="0 0 1 1"/>
      
      <!-- Shoulder Link -->
      <body name="shoulder_link" pos="0 0 0.163">
        <inertial mass="3.7" pos="0 0 0" diaginertia="0.0102675 0.0102675 0.00666"/>
        <joint name="shoulder_pan_joint" axis="0 0 1" range="-6.28319 6.28319" armature="0.1"/>
        <geom mesh="shoulder_0" material="urblue" type="mesh" contype="0" conaffinity="0" group="2"/>
        <geom mesh="shoulder_1" material="black" type="mesh" contype="0" conaffinity="0" group="2"/>
        <geom mesh="shoulder_2" material="jointgray" type="mesh" contype="0" conaffinity="0" group="2"/>
        <geom type="capsule" size="0.06 0.06" pos="0 0 -0.04" group="3"/>
        
        <!-- Upper Arm Link -->
        <body name="upper_arm_link" pos="0 0.138 0" quat="1 0 1 0">
          <inertial mass="8.393" pos="0 0 0.2125" diaginertia="0.133886 0.133886 0.0151074"/>
          <joint name="shoulder_lift_joint" axis="0 1 0" range="-6.28319 6.28319" armature="0.1"/>
          <geom mesh="upperarm_0" material="linkgray" type="mesh" contype="0" conaffinity="0" group="2"/>
          <geom mesh="upperarm_1" material="black" type="mesh" contype="0" conaffinity="0" group="2"/>
          <geom mesh="upperarm_2" material="jointgray" type="mesh" contype="0" conaffinity="0" group="2"/>
          <geom mesh="upperarm_3" material="urblue" type="mesh" contype="0" conaffinity="0" group="2"/>
          <geom type="capsule" pos="0 -0.04 0" quat="1 1 0 0" size="0.06 0.06" group="3"/>
          <geom type="capsule" size="0.05 0.2" pos="0 0 0.2" group="3"/>
          
          <!-- Forearm Link -->
          <body name="forearm_link" pos="0 -0.131 0.425">
            <inertial mass="2.275" pos="0 0 0.196" diaginertia="0.0311796 0.0311796 0.004095"/>
            <joint name="elbow_joint" axis="0 1 0" range="-3.1415 3.1415" armature="0.1"/>
            <geom mesh="forearm_0" material="urblue" type="mesh" contype="0" conaffinity="0" group="2"/>
            <geom mesh="forearm_1" material="linkgray" type="mesh" contype="0" conaffinity="0" group="2"/>
            <geom mesh="forearm_2" material="black" type="mesh" contype="0" conaffinity="0" group="2"/>
            <geom mesh="forearm_3" material="jointgray" type="mesh" contype="0" conaffinity="0" group="2"/>
            <geom type="capsule" pos="0 0.08 0" quat="1 1 0 0" size="0.055 0.06" group="3"/>
            <geom type="capsule" size="0.038 0.19" pos="0 0 0.2" group="3"/>
            
            <!-- Wrist 1 Link -->
            <body name="wrist_1_link" pos="0 0 0.392" quat="1 0 1 0">
              <inertial mass="1.219" pos="0 0.127 0" diaginertia="0.0025599 0.0025599 0.0021942"/>
              <joint name="wrist_1_joint" axis="0 1 0" range="-6.28319 6.28319" armature="0.1"/>
              <geom mesh="wrist1_0" material="black" type="mesh" contype="0" conaffinity="0" group="2"/>
              <geom mesh="wrist1_1" material="urblue" type="mesh" contype="0" conaffinity="0" group="2"/>
              <geom mesh="wrist1_2" material="jointgray" type="mesh" contype="0" conaffinity="0" group="2"/>
              <geom type="capsule" pos="0 0.05 0" quat="1 1 0 0" size="0.04 0.07" group="3"/>
              
              <!-- Wrist 2 Link -->
              <body name="wrist_2_link" pos="0 0.127 0">
                <inertial mass="1.219" pos="0 0 0.1" diaginertia="0.0025599 0.0025599 0.0021942"/>
                <joint name="wrist_2_joint" axis="0 0 1" range="-6.28319 6.28319" armature="0.1"/>
                <geom mesh="wrist2_0" material="black" type="mesh" contype="0" conaffinity="0" group="2"/>
                <geom mesh="wrist2_1" material="urblue" type="mesh" contype="0" conaffinity="0" group="2"/>
                <geom mesh="wrist2_2" material="jointgray" type="mesh" contype="0" conaffinity="0" group="2"/>
                <geom type="capsule" size="0.04 0.06" pos="0 0 0.04" group="3"/>
                <geom type="capsule" pos="0 0.02 0.1" quat="1 1 0 0" size="0.04 0.04" group="3"/>
                
                <!-- Wrist 3 Link -->
                <body name="wrist_3_link" pos="0 0 0.1">
                  <inertial mass="0.1889" pos="0 0.0771683 0" quat="1 0 0 1"
                    diaginertia="0.000132134 9.90863e-05 9.90863e-05"/>
                  <joint name="wrist_3_joint" axis="0 1 0" range="-6.28319 6.28319" armature="0.1"/>
                  <geom material="linkgray" mesh="wrist3" type="mesh" contype="0" conaffinity="0" group="2"/>
                  <geom type="cylinder" pos="0 0.08 0" quat="1 1 0 0" size="0.04 0.02" group="3"/>
                  <site name="eef_site" pos="0 0.1 0" quat="-1 1 0 0" size="0.01" rgba="1 0 0 0.5"/>
                </body>
              </body>
            </body>
          </body>
        </body>
      </body>
    </body>
  </worldbody>
</mujoco>
